<?xml version="1.0" encoding="utf-8"?>
<!-- This URDF was automatically created by SolidWorks to URDF Exporter! Originally created by Stephen Brawner (brawner@gmail.com) 
     Commit Version: 1.6.0-4-g7f85cfe  Build Version: 1.6.7995.38578
     For more information, please see http://wiki.ros.org/sw_urdf_exporter -->
<robot
  name="Ensamblee">
  <link
    name="base_link">
    <inertial>
      <origin
        xyz="0.035133 0.0010982 0.059578"
        rpy="0 0 0" />
      <mass
        value="1.6222" />
      <inertia
        ixx="0.0057091"
        ixy="0.00016017"
        ixz="-1.9562E-07"
        iyy="0.0078069"
        iyz="7.9795E-07"
        izz="0.01293" />
    </inertial>
    <visual>
      <origin
        xyz="0 0 0"
        rpy="0 0 0" />
      <geometry>
        <mesh
          filename="package://Ensamblee/meshes/base_link.STL" />
      </geometry>
      <material
        name="">
        <color
          rgba="0.79216 0.81961 0.93333 1" />
      </material>
    </visual>
    <collision>
      <origin
        xyz="0 0 0"
        rpy="0 0 0" />
      <geometry>
        <mesh
          filename="package://Ensamblee/meshes/base_link.STL" />
      </geometry>
    </collision>
  </link>
  <link
    name="base_giratoria">
    <inertial>
      <origin
        xyz="-0.00012545 -0.0015041 0.14037"
        rpy="0 0 0" />
      <mass
        value="0.27811" />
      <inertia
        ixx="0.00049658"
        ixy="-4.0519E-06"
        ixz="-2.3048E-07"
        iyy="0.00045443"
        iyz="-3.5467E-06"
        izz="0.00066548" />
    </inertial>
    <visual>
      <origin
        xyz="0 0 0"
        rpy="0 0 0" />
      <geometry>
        <mesh
          filename="package://Ensamblee/meshes/base_giratoria.STL" />
      </geometry>
      <material
        name="">
        <color
          rgba="1 1 1 1" />
      </material>
    </visual>
    <collision>
      <origin
        xyz="0 0 0"
        rpy="0 0 0" />
      <geometry>
        <mesh
          filename="package://Ensamblee/meshes/base_giratoria.STL" />
      </geometry>
    </collision>
  </link>
  <joint
    name="joint_1"
    type="revolute">
    <origin
      xyz="0 0 0"
      rpy="0 0 0" />
    <parent
      link="base_link" />
    <child
      link="base_giratoria" />
    <axis
      xyz="0 0 1" />
    <limit
      lower="-3.14"
      upper="3.14"
      effort="100"
      velocity="3.14" />
  </joint>
  <link
    name="brazo_inferior">
    <inertial>
      <origin
        xyz="0.10277 -0.010539 0.0045472"
        rpy="0 0 0" />
      <mass
        value="0.41319" />
      <inertia
        ixx="0.00031344"
        ixy="0.00016033"
        ixz="4.1036E-05"
        iyy="0.0018606"
        iyz="-4.2071E-06"
        izz="0.0017287" />
    </inertial>
    <visual>
      <origin
        xyz="0 0 0"
        rpy="0 0 0" />
      <geometry>
        <mesh
          filename="package://Ensamblee/meshes/brazo_inferior.STL" />
      </geometry>
      <material
        name="">
        <color
          rgba="0.79216 0.81961 0.93333 1" />
      </material>
    </visual>
    <collision>
      <origin
        xyz="0 0 0"
        rpy="0 0 0" />
      <geometry>
        <mesh
          filename="package://Ensamblee/meshes/brazo_inferior.STL" />
      </geometry>
    </collision>
  </link>
  <joint
    name="joint_2"
    type="revolute">
    <origin
      xyz="0.00032733 0.0034847 0.1945"
      rpy="1.6645 -1.5708 0" />
    <parent
      link="base_giratoria" />
    <child
      link="brazo_inferior" />
    <axis
      xyz="0 0 -1" />
    <limit
      lower="-1.57"
      upper="1.57"
      effort="100"
      velocity="3.14" />
  </joint>
  <link
    name="brazo_superior">
    <inertial>
      <origin
        xyz="0.049945 -0.003032 0.0023765"
        rpy="0 0 0" />
      <mass
        value="0.13139" />
      <inertia
        ixx="2.7543E-05"
        ixy="6.4343E-06"
        ixz="1.1157E-05"
        iyy="0.00016188"
        iyz="-6.8148E-07"
        izz="0.00016442" />
    </inertial>
    <visual>
      <origin
        xyz="0 0 0"
        rpy="0 0 0" />
      <geometry>
        <mesh
          filename="package://Ensamblee/meshes/brazo_superior.STL" />
      </geometry>
      <material
        name="">
        <color
          rgba="0.79216 0.81961 0.93333 1" />
      </material>
    </visual>
    <collision>
      <origin
        xyz="0 0 0"
        rpy="0 0 0" />
      <geometry>
        <mesh
          filename="package://Ensamblee/meshes/brazo_superior.STL" />
      </geometry>
    </collision>
  </link>
  <joint
    name="joint_3"
    type="revolute">
    <origin
      xyz="0.17906 -0.018361 0.00076231"
      rpy="0 0 -1.5708" />
    <parent
      link="brazo_inferior" />
    <child
      link="brazo_superior" />
    <axis
      xyz="0 0 -1" />
    <limit
      lower="-1.57"
      upper="1.57"
      effort="100"
      velocity="3.14" />
  </joint>
  <link
    name="dedo_1">
    <inertial>
      <origin
        xyz="0.044604 -0.011038 0.00099967"
        rpy="0 0 0" />
      <mass
        value="0.0045852" />
      <inertia
        ixx="1.1247E-07"
        ixy="-1.5654E-07"
        ixz="9.1993E-14"
        iyy="1.0476E-06"
        iyz="-7.4756E-13"
        izz="1.1404E-06" />
    </inertial>
    <visual>
      <origin
        xyz="0 0 0"
        rpy="0 0 0" />
      <geometry>
        <mesh
          filename="package://Ensamblee/meshes/dedo_1.STL" />
      </geometry>
      <material
        name="">
        <color
          rgba="0.79216 0.81961 0.93333 1" />
      </material>
    </visual>
    <collision>
      <origin
        xyz="0 0 0"
        rpy="0 0 0" />
      <geometry>
        <mesh
          filename="package://Ensamblee/meshes/dedo_1.STL" />
      </geometry>
    </collision>
  </link>
  <joint
    name="joint_4"
    type="revolute">
    <origin
      xyz="0.12475 -0.0039498 -0.0063922"
      rpy="2.2502 0.079705 0.017371" />
    <parent
      link="brazo_superior" />
    <child
      link="dedo_1" />
    <axis
      xyz="0 0 -1" />
    <limit
      lower="0"
      upper="0.5"
      effort="10"
      velocity="1" />
  </joint>
  <link
    name="dedo_2">
    <inertial>
      <origin
        xyz="0.04204 -0.018546 -0.001"
        rpy="0 0 0" />
      <mass
        value="0.0045852" />
      <inertia
        ixx="8.7082E-08"
        ixy="1.1185E-08"
        ixz="-3.7978E-14"
        iyy="1.0729E-06"
        iyz="-7.5224E-13"
        izz="1.1404E-06" />
    </inertial>
    <visual>
      <origin
        xyz="0 0 0"
        rpy="0 0 0" />
      <geometry>
        <mesh
          filename="package://Ensamblee/meshes/dedo_2.STL" />
      </geometry>
      <material
        name="">
        <color
          rgba="0.79216 0.81961 0.93333 1" />
      </material>
    </visual>
    <collision>
      <origin
        xyz="0 0 0"
        rpy="0 0 0" />
      <geometry>
        <mesh
          filename="package://Ensamblee/meshes/dedo_2.STL" />
      </geometry>
    </collision>
  </link>
  <joint
    name="joint_5"
    type="revolute">
    <origin
      xyz="0.12464 -0.0062567 0.008678"
      rpy="-1.942 0.065782 -0.072428" />
    <parent
      link="brazo_superior" />
    <child
      link="dedo_2" />
    <axis
      xyz="0 0 -1" />
    <limit
      lower="0"
      upper="0.5"
      effort="10"
      velocity="1" />
  </joint>
  <link
    name="dedo_3">
    <inertial>
      <origin
        xyz="0.042725 -0.01691 0.00099389"
        rpy="0 0 0" />
      <mass
        value="0.0045852" />
      <inertia
        ixx="8.7688E-08"
        ixy="-2.6872E-08"
        ixz="1.2559E-10"
        iyy="1.0723E-06"
        iyz="2.1926E-12"
        izz="1.1404E-06" />
    </inertial>
    <visual>
      <origin
        xyz="0 0 0"
        rpy="0 0 0" />
      <geometry>
        <mesh
          filename="package://Ensamblee/meshes/dedo_3.STL" />
      </geometry>
      <material
        name="">
        <color
          rgba="0.79216 0.81961 0.93333 1" />
      </material>
    </visual>
    <collision>
      <origin
        xyz="0 0 0"
        rpy="0 0 0" />
      <geometry>
        <mesh
          filename="package://Ensamblee/meshes/dedo_3.STL" />
      </geometry>
    </collision>
  </link>
  <joint
    name="joint_6"
    type="revolute">
    <origin
      xyz="0.12401 -0.019698 -0.0021097"
      rpy="0.15313 -0.0049958 -0.015269" />
    <parent
      link="brazo_superior" />
    <child
      link="dedo_3" />
    <axis
      xyz="0 0 -1" />
    <limit
      lower="0"
      upper="0.5"
      effort="10"
      velocity="1" />
  </joint>
</robot>